[2025-03-22T16:40:27.698+0000] {local_task_job_runner.py:123} INFO - ::group::Pre task execution logs
[2025-03-22T16:40:27.707+0000] {taskinstance.py:2614} INFO - Dependencies all met for dep_context=non-requeueable deps ti=<TaskInstance: fraud_detection_pipeline.connect_to_hive scheduled__2025-03-21T00:00:00+00:00 [queued]>
[2025-03-22T16:40:27.712+0000] {taskinstance.py:2614} INFO - Dependencies all met for dep_context=requeueable deps ti=<TaskInstance: fraud_detection_pipeline.connect_to_hive scheduled__2025-03-21T00:00:00+00:00 [queued]>
[2025-03-22T16:40:27.712+0000] {taskinstance.py:2867} INFO - Starting attempt 1 of 4
[2025-03-22T16:40:27.723+0000] {taskinstance.py:2890} INFO - Executing <Task(PythonOperator): connect_to_hive> on 2025-03-21 00:00:00+00:00
[2025-03-22T16:40:27.725+0000] {standard_task_runner.py:72} INFO - Started process 116821 to run task
[2025-03-22T16:40:27.727+0000] {standard_task_runner.py:104} INFO - Running: ['airflow', 'tasks', 'run', 'fraud_detection_pipeline', 'connect_to_hive', 'scheduled__2025-03-21T00:00:00+00:00', '--job-id', '23', '--raw', '--subdir', 'DAGS_FOLDER/dags.py', '--cfg-path', '/tmp/tmpibhcx264']
[2025-03-22T16:40:27.729+0000] {standard_task_runner.py:105} INFO - Job 23: Subtask connect_to_hive
[2025-03-22T16:40:27.751+0000] {task_command.py:467} INFO - Running <TaskInstance: fraud_detection_pipeline.connect_to_hive scheduled__2025-03-21T00:00:00+00:00 [running]> on host usmail-ThinkBook-14-G2-ITL
[2025-03-22T16:40:27.788+0000] {taskinstance.py:3134} INFO - Exporting env vars: AIRFLOW_CTX_DAG_OWNER='airflow' AIRFLOW_CTX_DAG_ID='fraud_detection_pipeline' AIRFLOW_CTX_TASK_ID='connect_to_hive' AIRFLOW_CTX_EXECUTION_DATE='2025-03-21T00:00:00+00:00' AIRFLOW_CTX_TRY_NUMBER='1' AIRFLOW_CTX_DAG_RUN_ID='scheduled__2025-03-21T00:00:00+00:00'
[2025-03-22T16:40:27.789+0000] {taskinstance.py:732} INFO - ::endgroup::
[2025-03-22T16:40:27.808+0000] {dags.py:157} ERROR - Error verifying Hive connection: Bad status: 3 (b'Error validating the login')
[2025-03-22T16:40:27.809+0000] {taskinstance.py:3313} ERROR - Task failed with exception
Traceback (most recent call last):
  File "/home/usmail/sys_fraud/sys_detection_frauds/lib/python3.12/site-packages/airflow/models/taskinstance.py", line 763, in _execute_task
    result = _execute_callable(context=context, **execute_callable_kwargs)
             ^^^^^^^^^^^^^^^^^^^^^^^^^^^^^^^^^^^^^^^^^^^^^^^^^^^^^^^^^^^^^
  File "/home/usmail/sys_fraud/sys_detection_frauds/lib/python3.12/site-packages/airflow/models/taskinstance.py", line 734, in _execute_callable
    return ExecutionCallableRunner(
           ^^^^^^^^^^^^^^^^^^^^^^^^
  File "/home/usmail/sys_fraud/sys_detection_frauds/lib/python3.12/site-packages/airflow/utils/operator_helpers.py", line 252, in run
    return self.func(*args, **kwargs)
           ^^^^^^^^^^^^^^^^^^^^^^^^^^
  File "/home/usmail/sys_fraud/sys_detection_frauds/lib/python3.12/site-packages/airflow/models/baseoperator.py", line 424, in wrapper
    return func(self, *args, **kwargs)
           ^^^^^^^^^^^^^^^^^^^^^^^^^^^
  File "/home/usmail/sys_fraud/sys_detection_frauds/lib/python3.12/site-packages/airflow/operators/python.py", line 238, in execute
    return_value = self.execute_callable()
                   ^^^^^^^^^^^^^^^^^^^^^^^
  File "/home/usmail/sys_fraud/sys_detection_frauds/lib/python3.12/site-packages/airflow/operators/python.py", line 256, in execute_callable
    return runner.run(*self.op_args, **self.op_kwargs)
           ^^^^^^^^^^^^^^^^^^^^^^^^^^^^^^^^^^^^^^^^^^^
  File "/home/usmail/sys_fraud/sys_detection_frauds/lib/python3.12/site-packages/airflow/utils/operator_helpers.py", line 252, in run
    return self.func(*args, **kwargs)
           ^^^^^^^^^^^^^^^^^^^^^^^^^^
  File "/home/usmail/sys_fraud/sys_detection_frauds/system_fraud_transactions_detection/airflow_home/dags/dags.py", line 140, in connect_to_hive
    conn = hive.Connection(
           ^^^^^^^^^^^^^^^^
  File "/home/usmail/sys_fraud/sys_detection_frauds/lib/python3.12/site-packages/pyhive/hive.py", line 269, in __init__
    self._transport.open()
  File "/home/usmail/sys_fraud/sys_detection_frauds/lib/python3.12/site-packages/thrift_sasl/__init__.py", line 95, in open
    raise TTransportException(type=TTransportException.NOT_OPEN,
thrift.transport.TTransport.TTransportException: Bad status: 3 (b'Error validating the login')
[2025-03-22T16:40:27.816+0000] {taskinstance.py:1226} INFO - Marking task as UP_FOR_RETRY. dag_id=fraud_detection_pipeline, task_id=connect_to_hive, run_id=scheduled__2025-03-21T00:00:00+00:00, execution_date=20250321T000000, start_date=20250322T164027, end_date=20250322T164027
[2025-03-22T16:40:27.829+0000] {taskinstance.py:341} INFO - ::group::Post task execution logs
[2025-03-22T16:40:27.829+0000] {standard_task_runner.py:124} ERROR - Failed to execute job 23 for task connect_to_hive (Bad status: 3 (b'Error validating the login'); 116821)
Traceback (most recent call last):
  File "/home/usmail/sys_fraud/sys_detection_frauds/lib/python3.12/site-packages/airflow/task/task_runner/standard_task_runner.py", line 117, in _start_by_fork
    ret = args.func(args, dag=self.dag)
          ^^^^^^^^^^^^^^^^^^^^^^^^^^^^^
  File "/home/usmail/sys_fraud/sys_detection_frauds/lib/python3.12/site-packages/airflow/cli/cli_config.py", line 49, in command
    return func(*args, **kwargs)
           ^^^^^^^^^^^^^^^^^^^^^
  File "/home/usmail/sys_fraud/sys_detection_frauds/lib/python3.12/site-packages/airflow/utils/cli.py", line 116, in wrapper
    return f(*args, **kwargs)
           ^^^^^^^^^^^^^^^^^^
  File "/home/usmail/sys_fraud/sys_detection_frauds/lib/python3.12/site-packages/airflow/cli/commands/task_command.py", line 483, in task_run
    task_return_code = _run_task_by_selected_method(args, _dag, ti)
                       ^^^^^^^^^^^^^^^^^^^^^^^^^^^^^^^^^^^^^^^^^^^^
  File "/home/usmail/sys_fraud/sys_detection_frauds/lib/python3.12/site-packages/airflow/cli/commands/task_command.py", line 256, in _run_task_by_selected_method
    return _run_raw_task(args, ti)
           ^^^^^^^^^^^^^^^^^^^^^^^
  File "/home/usmail/sys_fraud/sys_detection_frauds/lib/python3.12/site-packages/airflow/cli/commands/task_command.py", line 341, in _run_raw_task
    return ti._run_raw_task(
           ^^^^^^^^^^^^^^^^^
  File "/home/usmail/sys_fraud/sys_detection_frauds/lib/python3.12/site-packages/airflow/utils/session.py", line 97, in wrapper
    return func(*args, session=session, **kwargs)
           ^^^^^^^^^^^^^^^^^^^^^^^^^^^^^^^^^^^^^^
  File "/home/usmail/sys_fraud/sys_detection_frauds/lib/python3.12/site-packages/airflow/models/taskinstance.py", line 3006, in _run_raw_task
    return _run_raw_task(
           ^^^^^^^^^^^^^^
  File "/home/usmail/sys_fraud/sys_detection_frauds/lib/python3.12/site-packages/airflow/models/taskinstance.py", line 274, in _run_raw_task
    TaskInstance._execute_task_with_callbacks(
  File "/home/usmail/sys_fraud/sys_detection_frauds/lib/python3.12/site-packages/airflow/models/taskinstance.py", line 3161, in _execute_task_with_callbacks
    result = self._execute_task(context, task_orig)
             ^^^^^^^^^^^^^^^^^^^^^^^^^^^^^^^^^^^^^^
  File "/home/usmail/sys_fraud/sys_detection_frauds/lib/python3.12/site-packages/airflow/models/taskinstance.py", line 3185, in _execute_task
    return _execute_task(self, context, task_orig)
           ^^^^^^^^^^^^^^^^^^^^^^^^^^^^^^^^^^^^^^^
  File "/home/usmail/sys_fraud/sys_detection_frauds/lib/python3.12/site-packages/airflow/models/taskinstance.py", line 763, in _execute_task
    result = _execute_callable(context=context, **execute_callable_kwargs)
             ^^^^^^^^^^^^^^^^^^^^^^^^^^^^^^^^^^^^^^^^^^^^^^^^^^^^^^^^^^^^^
  File "/home/usmail/sys_fraud/sys_detection_frauds/lib/python3.12/site-packages/airflow/models/taskinstance.py", line 734, in _execute_callable
    return ExecutionCallableRunner(
           ^^^^^^^^^^^^^^^^^^^^^^^^
  File "/home/usmail/sys_fraud/sys_detection_frauds/lib/python3.12/site-packages/airflow/utils/operator_helpers.py", line 252, in run
    return self.func(*args, **kwargs)
           ^^^^^^^^^^^^^^^^^^^^^^^^^^
  File "/home/usmail/sys_fraud/sys_detection_frauds/lib/python3.12/site-packages/airflow/models/baseoperator.py", line 424, in wrapper
    return func(self, *args, **kwargs)
           ^^^^^^^^^^^^^^^^^^^^^^^^^^^
  File "/home/usmail/sys_fraud/sys_detection_frauds/lib/python3.12/site-packages/airflow/operators/python.py", line 238, in execute
    return_value = self.execute_callable()
                   ^^^^^^^^^^^^^^^^^^^^^^^
  File "/home/usmail/sys_fraud/sys_detection_frauds/lib/python3.12/site-packages/airflow/operators/python.py", line 256, in execute_callable
    return runner.run(*self.op_args, **self.op_kwargs)
           ^^^^^^^^^^^^^^^^^^^^^^^^^^^^^^^^^^^^^^^^^^^
  File "/home/usmail/sys_fraud/sys_detection_frauds/lib/python3.12/site-packages/airflow/utils/operator_helpers.py", line 252, in run
    return self.func(*args, **kwargs)
           ^^^^^^^^^^^^^^^^^^^^^^^^^^
  File "/home/usmail/sys_fraud/sys_detection_frauds/system_fraud_transactions_detection/airflow_home/dags/dags.py", line 140, in connect_to_hive
    conn = hive.Connection(
           ^^^^^^^^^^^^^^^^
  File "/home/usmail/sys_fraud/sys_detection_frauds/lib/python3.12/site-packages/pyhive/hive.py", line 269, in __init__
    self._transport.open()
  File "/home/usmail/sys_fraud/sys_detection_frauds/lib/python3.12/site-packages/thrift_sasl/__init__.py", line 95, in open
    raise TTransportException(type=TTransportException.NOT_OPEN,
thrift.transport.TTransport.TTransportException: Bad status: 3 (b'Error validating the login')
[2025-03-22T16:40:27.859+0000] {local_task_job_runner.py:266} INFO - Task exited with return code 1
[2025-03-22T16:40:27.884+0000] {taskinstance.py:3901} INFO - 0 downstream tasks scheduled from follow-on schedule check
[2025-03-22T16:40:27.884+0000] {local_task_job_runner.py:245} INFO - ::endgroup::
