[2025-03-22T17:47:39.154+0000] {local_task_job_runner.py:123} INFO - ::group::Pre task execution logs
[2025-03-22T17:47:39.164+0000] {taskinstance.py:2614} INFO - Dependencies all met for dep_context=non-requeueable deps ti=<TaskInstance: fraud_detection_pipeline.create_tables scheduled__2025-03-21T00:00:00+00:00 [queued]>
[2025-03-22T17:47:39.172+0000] {taskinstance.py:2614} INFO - Dependencies all met for dep_context=requeueable deps ti=<TaskInstance: fraud_detection_pipeline.create_tables scheduled__2025-03-21T00:00:00+00:00 [queued]>
[2025-03-22T17:47:39.172+0000] {taskinstance.py:2867} INFO - Starting attempt 9 of 12
[2025-03-22T17:47:39.183+0000] {taskinstance.py:2890} INFO - Executing <Task(PythonOperator): create_tables> on 2025-03-21 00:00:00+00:00
[2025-03-22T17:47:39.188+0000] {standard_task_runner.py:72} INFO - Started process 166779 to run task
[2025-03-22T17:47:39.190+0000] {standard_task_runner.py:104} INFO - Running: ['airflow', 'tasks', 'run', 'fraud_detection_pipeline', 'create_tables', 'scheduled__2025-03-21T00:00:00+00:00', '--job-id', '40', '--raw', '--subdir', 'DAGS_FOLDER/dags.py', '--cfg-path', '/tmp/tmpbm4ypv7j']
[2025-03-22T17:47:39.192+0000] {standard_task_runner.py:105} INFO - Job 40: Subtask create_tables
[2025-03-22T17:47:39.227+0000] {task_command.py:467} INFO - Running <TaskInstance: fraud_detection_pipeline.create_tables scheduled__2025-03-21T00:00:00+00:00 [running]> on host usmail-ThinkBook-14-G2-ITL
[2025-03-22T17:47:39.281+0000] {taskinstance.py:3134} INFO - Exporting env vars: AIRFLOW_CTX_DAG_OWNER='airflow' AIRFLOW_CTX_DAG_ID='fraud_detection_pipeline' AIRFLOW_CTX_TASK_ID='create_tables' AIRFLOW_CTX_EXECUTION_DATE='2025-03-21T00:00:00+00:00' AIRFLOW_CTX_TRY_NUMBER='9' AIRFLOW_CTX_DAG_RUN_ID='scheduled__2025-03-21T00:00:00+00:00'
[2025-03-22T17:47:39.281+0000] {taskinstance.py:732} INFO - ::endgroup::
[2025-03-22T17:47:39.306+0000] {hive.py:475} INFO - USE `default`
[2025-03-22T17:47:39.315+0000] {hive.py:475} INFO - 
        CREATE TABLE IF NOT EXISTS customers (
            customer_id STRING, 
            account_history ARRAY<STRING>, 
            age INT,
            location STRING,
            avg_transaction_value STRING
        )
        LOCATION 'hdfs://namenode:9000/hive_warehouse'
        
[2025-03-22T17:47:40.327+0000] {dags.py:228} ERROR - Error creating Hive tables: TExecuteStatementResp(status=TStatus(statusCode=3, infoMessages=['Server-side error; please check HS2 logs.'], sqlState='08S01', errorCode=40000, errorMessage='Error while compiling statement: FAILED: Execution Error, return code 40000 from org.apache.hadoop.hive.ql.ddl.DDLTask. MetaException(message:Got exception: java.net.ConnectException Call From hiveserver2/172.18.0.6 to namenode:9000 failed on connection exception: java.net.ConnectException: Connection refused; For more details see:  http://wiki.apache.org/hadoop/ConnectionRefused)'), operationHandle=None)
[2025-03-22T17:47:40.328+0000] {taskinstance.py:3313} ERROR - Task failed with exception
Traceback (most recent call last):
  File "/home/usmail/sys_fraud/sys_detection_frauds/lib/python3.12/site-packages/airflow/models/taskinstance.py", line 763, in _execute_task
    result = _execute_callable(context=context, **execute_callable_kwargs)
             ^^^^^^^^^^^^^^^^^^^^^^^^^^^^^^^^^^^^^^^^^^^^^^^^^^^^^^^^^^^^^
  File "/home/usmail/sys_fraud/sys_detection_frauds/lib/python3.12/site-packages/airflow/models/taskinstance.py", line 734, in _execute_callable
    return ExecutionCallableRunner(
           ^^^^^^^^^^^^^^^^^^^^^^^^
  File "/home/usmail/sys_fraud/sys_detection_frauds/lib/python3.12/site-packages/airflow/utils/operator_helpers.py", line 252, in run
    return self.func(*args, **kwargs)
           ^^^^^^^^^^^^^^^^^^^^^^^^^^
  File "/home/usmail/sys_fraud/sys_detection_frauds/lib/python3.12/site-packages/airflow/models/baseoperator.py", line 424, in wrapper
    return func(self, *args, **kwargs)
           ^^^^^^^^^^^^^^^^^^^^^^^^^^^
  File "/home/usmail/sys_fraud/sys_detection_frauds/lib/python3.12/site-packages/airflow/operators/python.py", line 238, in execute
    return_value = self.execute_callable()
                   ^^^^^^^^^^^^^^^^^^^^^^^
  File "/home/usmail/sys_fraud/sys_detection_frauds/lib/python3.12/site-packages/airflow/operators/python.py", line 256, in execute_callable
    return runner.run(*self.op_args, **self.op_kwargs)
           ^^^^^^^^^^^^^^^^^^^^^^^^^^^^^^^^^^^^^^^^^^^
  File "/home/usmail/sys_fraud/sys_detection_frauds/lib/python3.12/site-packages/airflow/utils/operator_helpers.py", line 252, in run
    return self.func(*args, **kwargs)
           ^^^^^^^^^^^^^^^^^^^^^^^^^^
  File "/home/usmail/sys_fraud/sys_detection_frauds/system_fraud_transactions_detection/airflow_home/dags/dags.py", line 215, in create_tables
    cursor.execute(create_table_customers)
  File "/home/usmail/sys_fraud/sys_detection_frauds/lib/python3.12/site-packages/pyhive/hive.py", line 481, in execute
    _check_status(response)
  File "/home/usmail/sys_fraud/sys_detection_frauds/lib/python3.12/site-packages/pyhive/hive.py", line 611, in _check_status
    raise OperationalError(response)
pyhive.exc.OperationalError: TExecuteStatementResp(status=TStatus(statusCode=3, infoMessages=['Server-side error; please check HS2 logs.'], sqlState='08S01', errorCode=40000, errorMessage='Error while compiling statement: FAILED: Execution Error, return code 40000 from org.apache.hadoop.hive.ql.ddl.DDLTask. MetaException(message:Got exception: java.net.ConnectException Call From hiveserver2/172.18.0.6 to namenode:9000 failed on connection exception: java.net.ConnectException: Connection refused; For more details see:  http://wiki.apache.org/hadoop/ConnectionRefused)'), operationHandle=None)
[2025-03-22T17:47:40.337+0000] {taskinstance.py:1226} INFO - Marking task as UP_FOR_RETRY. dag_id=fraud_detection_pipeline, task_id=create_tables, run_id=scheduled__2025-03-21T00:00:00+00:00, execution_date=20250321T000000, start_date=20250322T174739, end_date=20250322T174740
[2025-03-22T17:47:40.356+0000] {taskinstance.py:341} INFO - ::group::Post task execution logs
[2025-03-22T17:47:40.356+0000] {standard_task_runner.py:124} ERROR - Failed to execute job 40 for task create_tables (TExecuteStatementResp(status=TStatus(statusCode=3, infoMessages=['Server-side error; please check HS2 logs.'], sqlState='08S01', errorCode=40000, errorMessage='Error while compiling statement: FAILED: Execution Error, return code 40000 from org.apache.hadoop.hive.ql.ddl.DDLTask. MetaException(message:Got exception: java.net.ConnectException Call From hiveserver2/172.18.0.6 to namenode:9000 failed on connection exception: java.net.ConnectException: Connection refused; For more details see:  http://wiki.apache.org/hadoop/ConnectionRefused)'), operationHandle=None); 166779)
Traceback (most recent call last):
  File "/home/usmail/sys_fraud/sys_detection_frauds/lib/python3.12/site-packages/airflow/task/task_runner/standard_task_runner.py", line 117, in _start_by_fork
    ret = args.func(args, dag=self.dag)
          ^^^^^^^^^^^^^^^^^^^^^^^^^^^^^
  File "/home/usmail/sys_fraud/sys_detection_frauds/lib/python3.12/site-packages/airflow/cli/cli_config.py", line 49, in command
    return func(*args, **kwargs)
           ^^^^^^^^^^^^^^^^^^^^^
  File "/home/usmail/sys_fraud/sys_detection_frauds/lib/python3.12/site-packages/airflow/utils/cli.py", line 116, in wrapper
    return f(*args, **kwargs)
           ^^^^^^^^^^^^^^^^^^
  File "/home/usmail/sys_fraud/sys_detection_frauds/lib/python3.12/site-packages/airflow/cli/commands/task_command.py", line 483, in task_run
    task_return_code = _run_task_by_selected_method(args, _dag, ti)
                       ^^^^^^^^^^^^^^^^^^^^^^^^^^^^^^^^^^^^^^^^^^^^
  File "/home/usmail/sys_fraud/sys_detection_frauds/lib/python3.12/site-packages/airflow/cli/commands/task_command.py", line 256, in _run_task_by_selected_method
    return _run_raw_task(args, ti)
           ^^^^^^^^^^^^^^^^^^^^^^^
  File "/home/usmail/sys_fraud/sys_detection_frauds/lib/python3.12/site-packages/airflow/cli/commands/task_command.py", line 341, in _run_raw_task
    return ti._run_raw_task(
           ^^^^^^^^^^^^^^^^^
  File "/home/usmail/sys_fraud/sys_detection_frauds/lib/python3.12/site-packages/airflow/utils/session.py", line 97, in wrapper
    return func(*args, session=session, **kwargs)
           ^^^^^^^^^^^^^^^^^^^^^^^^^^^^^^^^^^^^^^
  File "/home/usmail/sys_fraud/sys_detection_frauds/lib/python3.12/site-packages/airflow/models/taskinstance.py", line 3006, in _run_raw_task
    return _run_raw_task(
           ^^^^^^^^^^^^^^
  File "/home/usmail/sys_fraud/sys_detection_frauds/lib/python3.12/site-packages/airflow/models/taskinstance.py", line 274, in _run_raw_task
    TaskInstance._execute_task_with_callbacks(
  File "/home/usmail/sys_fraud/sys_detection_frauds/lib/python3.12/site-packages/airflow/models/taskinstance.py", line 3161, in _execute_task_with_callbacks
    result = self._execute_task(context, task_orig)
             ^^^^^^^^^^^^^^^^^^^^^^^^^^^^^^^^^^^^^^
  File "/home/usmail/sys_fraud/sys_detection_frauds/lib/python3.12/site-packages/airflow/models/taskinstance.py", line 3185, in _execute_task
    return _execute_task(self, context, task_orig)
           ^^^^^^^^^^^^^^^^^^^^^^^^^^^^^^^^^^^^^^^
  File "/home/usmail/sys_fraud/sys_detection_frauds/lib/python3.12/site-packages/airflow/models/taskinstance.py", line 763, in _execute_task
    result = _execute_callable(context=context, **execute_callable_kwargs)
             ^^^^^^^^^^^^^^^^^^^^^^^^^^^^^^^^^^^^^^^^^^^^^^^^^^^^^^^^^^^^^
  File "/home/usmail/sys_fraud/sys_detection_frauds/lib/python3.12/site-packages/airflow/models/taskinstance.py", line 734, in _execute_callable
    return ExecutionCallableRunner(
           ^^^^^^^^^^^^^^^^^^^^^^^^
  File "/home/usmail/sys_fraud/sys_detection_frauds/lib/python3.12/site-packages/airflow/utils/operator_helpers.py", line 252, in run
    return self.func(*args, **kwargs)
           ^^^^^^^^^^^^^^^^^^^^^^^^^^
  File "/home/usmail/sys_fraud/sys_detection_frauds/lib/python3.12/site-packages/airflow/models/baseoperator.py", line 424, in wrapper
    return func(self, *args, **kwargs)
           ^^^^^^^^^^^^^^^^^^^^^^^^^^^
  File "/home/usmail/sys_fraud/sys_detection_frauds/lib/python3.12/site-packages/airflow/operators/python.py", line 238, in execute
    return_value = self.execute_callable()
                   ^^^^^^^^^^^^^^^^^^^^^^^
  File "/home/usmail/sys_fraud/sys_detection_frauds/lib/python3.12/site-packages/airflow/operators/python.py", line 256, in execute_callable
    return runner.run(*self.op_args, **self.op_kwargs)
           ^^^^^^^^^^^^^^^^^^^^^^^^^^^^^^^^^^^^^^^^^^^
  File "/home/usmail/sys_fraud/sys_detection_frauds/lib/python3.12/site-packages/airflow/utils/operator_helpers.py", line 252, in run
    return self.func(*args, **kwargs)
           ^^^^^^^^^^^^^^^^^^^^^^^^^^
  File "/home/usmail/sys_fraud/sys_detection_frauds/system_fraud_transactions_detection/airflow_home/dags/dags.py", line 215, in create_tables
    cursor.execute(create_table_customers)
  File "/home/usmail/sys_fraud/sys_detection_frauds/lib/python3.12/site-packages/pyhive/hive.py", line 481, in execute
    _check_status(response)
  File "/home/usmail/sys_fraud/sys_detection_frauds/lib/python3.12/site-packages/pyhive/hive.py", line 611, in _check_status
    raise OperationalError(response)
pyhive.exc.OperationalError: TExecuteStatementResp(status=TStatus(statusCode=3, infoMessages=['Server-side error; please check HS2 logs.'], sqlState='08S01', errorCode=40000, errorMessage='Error while compiling statement: FAILED: Execution Error, return code 40000 from org.apache.hadoop.hive.ql.ddl.DDLTask. MetaException(message:Got exception: java.net.ConnectException Call From hiveserver2/172.18.0.6 to namenode:9000 failed on connection exception: java.net.ConnectException: Connection refused; For more details see:  http://wiki.apache.org/hadoop/ConnectionRefused)'), operationHandle=None)
[2025-03-22T17:47:40.366+0000] {local_task_job_runner.py:266} INFO - Task exited with return code 1
[2025-03-22T17:47:40.393+0000] {taskinstance.py:3901} INFO - 0 downstream tasks scheduled from follow-on schedule check
[2025-03-22T17:47:40.394+0000] {local_task_job_runner.py:245} INFO - ::endgroup::
