[2025-03-22T21:57:42.181+0000] {local_task_job_runner.py:123} INFO - ::group::Pre task execution logs
[2025-03-22T21:57:42.191+0000] {taskinstance.py:2614} INFO - Dependencies all met for dep_context=non-requeueable deps ti=<TaskInstance: fraud_detection_pipeline.create_tables scheduled__2025-03-21T00:00:00+00:00 [queued]>
[2025-03-22T21:57:42.197+0000] {taskinstance.py:2614} INFO - Dependencies all met for dep_context=requeueable deps ti=<TaskInstance: fraud_detection_pipeline.create_tables scheduled__2025-03-21T00:00:00+00:00 [queued]>
[2025-03-22T21:57:42.197+0000] {taskinstance.py:2867} INFO - Starting attempt 17 of 20
[2025-03-22T21:57:42.219+0000] {taskinstance.py:2890} INFO - Executing <Task(PythonOperator): create_tables> on 2025-03-21 00:00:00+00:00
[2025-03-22T21:57:42.224+0000] {standard_task_runner.py:72} INFO - Started process 529106 to run task
[2025-03-22T21:57:42.228+0000] {standard_task_runner.py:104} INFO - Running: ['airflow', 'tasks', 'run', 'fraud_detection_pipeline', 'create_tables', 'scheduled__2025-03-21T00:00:00+00:00', '--job-id', '108', '--raw', '--subdir', 'DAGS_FOLDER/dags.py', '--cfg-path', '/tmp/tmpwgv3p1i9']
[2025-03-22T21:57:42.229+0000] {standard_task_runner.py:105} INFO - Job 108: Subtask create_tables
[2025-03-22T21:57:42.264+0000] {task_command.py:467} INFO - Running <TaskInstance: fraud_detection_pipeline.create_tables scheduled__2025-03-21T00:00:00+00:00 [running]> on host usmail-ThinkBook-14-G2-ITL
[2025-03-22T21:57:42.329+0000] {taskinstance.py:3134} INFO - Exporting env vars: AIRFLOW_CTX_DAG_EMAIL='ismailsamilacc@gmail.com' AIRFLOW_CTX_DAG_OWNER='airflow' AIRFLOW_CTX_DAG_ID='fraud_detection_pipeline' AIRFLOW_CTX_TASK_ID='create_tables' AIRFLOW_CTX_EXECUTION_DATE='2025-03-21T00:00:00+00:00' AIRFLOW_CTX_TRY_NUMBER='17' AIRFLOW_CTX_DAG_RUN_ID='scheduled__2025-03-21T00:00:00+00:00'
[2025-03-22T21:57:42.329+0000] {taskinstance.py:732} INFO - ::endgroup::
[2025-03-22T21:57:42.365+0000] {hive.py:475} INFO - USE `default`
[2025-03-22T21:57:42.370+0000] {hive.py:475} INFO - 
        CREATE TABLE IF NOT EXISTS customers (
            customer_id STRING, 
            account_history ARRAY<STRING>, 
            age INT,
            location STRING,
            avg_transaction_value STRING
        )
        LOCATION 'hdfs://namenode:9001/hive_warehouse'
        
[2025-03-22T21:57:42.379+0000] {hive.py:475} INFO - 
        CREATE TABLE  IF NOT EXISTS  transactions (
        transaction_id STRING,
        date_time TIMESTAMP,
        amount DOUBLE,
        currency STRING,
        merchant_details STRING,
        customer_id STRING,
        transaction_type STRING,
        location STRING
        )
         LOCATION 'hdfs://namenode:9001/hive_warehouse'
        
        
[2025-03-22T21:57:42.385+0000] {hive.py:475} INFO - 
        CREATE TABLE  IF NOT EXISTS  external_data (
        blacklist_info ARRAY<STRING>,
        credit_scores MAP<STRING, INT>,
        fraud_reports MAP<STRING, INT>


        )
         LOCATION 'hdfs://namenode:9001/hive_warehouse'
        
[2025-03-22T21:57:42.391+0000] {dags.py:214} ERROR - Error creating Hive tables: name 'hchgscgs' is not defined
[2025-03-22T21:57:42.391+0000] {taskinstance.py:3313} ERROR - Task failed with exception
Traceback (most recent call last):
  File "/home/usmail/sys_fraud/sys_detection_frauds/lib/python3.12/site-packages/airflow/models/taskinstance.py", line 763, in _execute_task
    result = _execute_callable(context=context, **execute_callable_kwargs)
             ^^^^^^^^^^^^^^^^^^^^^^^^^^^^^^^^^^^^^^^^^^^^^^^^^^^^^^^^^^^^^
  File "/home/usmail/sys_fraud/sys_detection_frauds/lib/python3.12/site-packages/airflow/models/taskinstance.py", line 734, in _execute_callable
    return ExecutionCallableRunner(
           ^^^^^^^^^^^^^^^^^^^^^^^^
  File "/home/usmail/sys_fraud/sys_detection_frauds/lib/python3.12/site-packages/airflow/utils/operator_helpers.py", line 252, in run
    return self.func(*args, **kwargs)
           ^^^^^^^^^^^^^^^^^^^^^^^^^^
  File "/home/usmail/sys_fraud/sys_detection_frauds/lib/python3.12/site-packages/airflow/models/baseoperator.py", line 424, in wrapper
    return func(self, *args, **kwargs)
           ^^^^^^^^^^^^^^^^^^^^^^^^^^^
  File "/home/usmail/sys_fraud/sys_detection_frauds/lib/python3.12/site-packages/airflow/operators/python.py", line 238, in execute
    return_value = self.execute_callable()
                   ^^^^^^^^^^^^^^^^^^^^^^^
  File "/home/usmail/sys_fraud/sys_detection_frauds/lib/python3.12/site-packages/airflow/operators/python.py", line 256, in execute_callable
    return runner.run(*self.op_args, **self.op_kwargs)
           ^^^^^^^^^^^^^^^^^^^^^^^^^^^^^^^^^^^^^^^^^^^
  File "/home/usmail/sys_fraud/sys_detection_frauds/lib/python3.12/site-packages/airflow/utils/operator_helpers.py", line 252, in run
    return self.func(*args, **kwargs)
           ^^^^^^^^^^^^^^^^^^^^^^^^^^
  File "/home/usmail/sys_fraud/sys_detection_frauds/system_fraud_transactions_detection/airflow_home/dags/dags.py", line 206, in create_tables
    hchgscgs
NameError: name 'hchgscgs' is not defined
[2025-03-22T21:57:42.404+0000] {taskinstance.py:1226} INFO - Marking task as UP_FOR_RETRY. dag_id=fraud_detection_pipeline, task_id=create_tables, run_id=scheduled__2025-03-21T00:00:00+00:00, execution_date=20250321T000000, start_date=20250322T215742, end_date=20250322T215742
[2025-03-22T21:57:42.424+0000] {logging_mixin.py:190} WARNING - /home/usmail/sys_fraud/sys_detection_frauds/lib/python3.12/site-packages/airflow/utils/email.py:155 RemovedInAirflow3Warning: Fetching SMTP credentials from configuration variables will be deprecated in a future release. Please set credentials using a connection instead.
[2025-03-22T21:57:42.425+0000] {configuration.py:1074} WARNING - section/key [smtp/smtp_user] not found in config
[2025-03-22T21:57:42.425+0000] {email.py:272} INFO - Email alerting: attempt 1
[2025-03-22T21:57:42.434+0000] {configuration.py:1074} WARNING - section/key [smtp/smtp_user] not found in config
[2025-03-22T21:57:42.435+0000] {email.py:272} INFO - Email alerting: attempt 1
[2025-03-22T21:57:42.435+0000] {taskinstance.py:1235} ERROR - Failed to send email to: ['ismailsamilacc@gmail.com']
Traceback (most recent call last):
  File "/home/usmail/sys_fraud/sys_detection_frauds/lib/python3.12/site-packages/airflow/models/taskinstance.py", line 274, in _run_raw_task
    TaskInstance._execute_task_with_callbacks(
  File "/home/usmail/sys_fraud/sys_detection_frauds/lib/python3.12/site-packages/airflow/models/taskinstance.py", line 3161, in _execute_task_with_callbacks
    result = self._execute_task(context, task_orig)
             ^^^^^^^^^^^^^^^^^^^^^^^^^^^^^^^^^^^^^^
  File "/home/usmail/sys_fraud/sys_detection_frauds/lib/python3.12/site-packages/airflow/models/taskinstance.py", line 3185, in _execute_task
    return _execute_task(self, context, task_orig)
           ^^^^^^^^^^^^^^^^^^^^^^^^^^^^^^^^^^^^^^^
  File "/home/usmail/sys_fraud/sys_detection_frauds/lib/python3.12/site-packages/airflow/models/taskinstance.py", line 763, in _execute_task
    result = _execute_callable(context=context, **execute_callable_kwargs)
             ^^^^^^^^^^^^^^^^^^^^^^^^^^^^^^^^^^^^^^^^^^^^^^^^^^^^^^^^^^^^^
  File "/home/usmail/sys_fraud/sys_detection_frauds/lib/python3.12/site-packages/airflow/models/taskinstance.py", line 734, in _execute_callable
    return ExecutionCallableRunner(
           ^^^^^^^^^^^^^^^^^^^^^^^^
  File "/home/usmail/sys_fraud/sys_detection_frauds/lib/python3.12/site-packages/airflow/utils/operator_helpers.py", line 252, in run
    return self.func(*args, **kwargs)
           ^^^^^^^^^^^^^^^^^^^^^^^^^^
  File "/home/usmail/sys_fraud/sys_detection_frauds/lib/python3.12/site-packages/airflow/models/baseoperator.py", line 424, in wrapper
    return func(self, *args, **kwargs)
           ^^^^^^^^^^^^^^^^^^^^^^^^^^^
  File "/home/usmail/sys_fraud/sys_detection_frauds/lib/python3.12/site-packages/airflow/operators/python.py", line 238, in execute
    return_value = self.execute_callable()
                   ^^^^^^^^^^^^^^^^^^^^^^^
  File "/home/usmail/sys_fraud/sys_detection_frauds/lib/python3.12/site-packages/airflow/operators/python.py", line 256, in execute_callable
    return runner.run(*self.op_args, **self.op_kwargs)
           ^^^^^^^^^^^^^^^^^^^^^^^^^^^^^^^^^^^^^^^^^^^
  File "/home/usmail/sys_fraud/sys_detection_frauds/lib/python3.12/site-packages/airflow/utils/operator_helpers.py", line 252, in run
    return self.func(*args, **kwargs)
           ^^^^^^^^^^^^^^^^^^^^^^^^^^
  File "/home/usmail/sys_fraud/sys_detection_frauds/system_fraud_transactions_detection/airflow_home/dags/dags.py", line 206, in create_tables
    hchgscgs
NameError: name 'hchgscgs' is not defined

During handling of the above exception, another exception occurred:

Traceback (most recent call last):
  File "/home/usmail/sys_fraud/sys_detection_frauds/lib/python3.12/site-packages/airflow/models/taskinstance.py", line 1443, in _email_alert
    send_email(task.email, subject, html_content)
  File "/home/usmail/sys_fraud/sys_detection_frauds/lib/python3.12/site-packages/airflow/utils/email.py", line 80, in send_email
    return backend(
           ^^^^^^^^
  File "/home/usmail/sys_fraud/sys_detection_frauds/lib/python3.12/site-packages/airflow/utils/email.py", line 155, in send_email_smtp
    send_mime_email(e_from=mail_from, e_to=recipients, mime_msg=msg, conn_id=conn_id, dryrun=dryrun)
  File "/home/usmail/sys_fraud/sys_detection_frauds/lib/python3.12/site-packages/airflow/utils/email.py", line 274, in send_mime_email
    smtp_conn = _get_smtp_connection(smtp_host, smtp_port, smtp_timeout, smtp_ssl)
                ^^^^^^^^^^^^^^^^^^^^^^^^^^^^^^^^^^^^^^^^^^^^^^^^^^^^^^^^^^^^^^^^^^
  File "/home/usmail/sys_fraud/sys_detection_frauds/lib/python3.12/site-packages/airflow/utils/email.py", line 318, in _get_smtp_connection
    return smtplib.SMTP(host=host, port=port, timeout=timeout)
           ^^^^^^^^^^^^^^^^^^^^^^^^^^^^^^^^^^^^^^^^^^^^^^^^^^^
  File "/usr/lib/python3.12/smtplib.py", line 255, in __init__
    (code, msg) = self.connect(host, port)
                  ^^^^^^^^^^^^^^^^^^^^^^^^
  File "/usr/lib/python3.12/smtplib.py", line 341, in connect
    self.sock = self._get_socket(host, port, self.timeout)
                ^^^^^^^^^^^^^^^^^^^^^^^^^^^^^^^^^^^^^^^^^^
  File "/usr/lib/python3.12/smtplib.py", line 312, in _get_socket
    return socket.create_connection((host, port), timeout,
           ^^^^^^^^^^^^^^^^^^^^^^^^^^^^^^^^^^^^^^^^^^^^^^^
  File "/usr/lib/python3.12/socket.py", line 852, in create_connection
    raise exceptions[0]
  File "/usr/lib/python3.12/socket.py", line 837, in create_connection
    sock.connect(sa)
ConnectionRefusedError: [Errno 111] Connection refused

During handling of the above exception, another exception occurred:

Traceback (most recent call last):
  File "/home/usmail/sys_fraud/sys_detection_frauds/lib/python3.12/site-packages/airflow/models/taskinstance.py", line 1233, in _handle_failure
    task_instance.email_alert(error, failure_context["task"])
  File "/home/usmail/sys_fraud/sys_detection_frauds/lib/python3.12/site-packages/airflow/models/taskinstance.py", line 3611, in email_alert
    _email_alert(task_instance=self, exception=exception, task=task)
  File "/home/usmail/sys_fraud/sys_detection_frauds/lib/python3.12/site-packages/airflow/models/taskinstance.py", line 1445, in _email_alert
    send_email(task.email, subject, html_content_err)
  File "/home/usmail/sys_fraud/sys_detection_frauds/lib/python3.12/site-packages/airflow/utils/email.py", line 80, in send_email
    return backend(
           ^^^^^^^^
  File "/home/usmail/sys_fraud/sys_detection_frauds/lib/python3.12/site-packages/airflow/utils/email.py", line 155, in send_email_smtp
    send_mime_email(e_from=mail_from, e_to=recipients, mime_msg=msg, conn_id=conn_id, dryrun=dryrun)
  File "/home/usmail/sys_fraud/sys_detection_frauds/lib/python3.12/site-packages/airflow/utils/email.py", line 274, in send_mime_email
    smtp_conn = _get_smtp_connection(smtp_host, smtp_port, smtp_timeout, smtp_ssl)
                ^^^^^^^^^^^^^^^^^^^^^^^^^^^^^^^^^^^^^^^^^^^^^^^^^^^^^^^^^^^^^^^^^^
  File "/home/usmail/sys_fraud/sys_detection_frauds/lib/python3.12/site-packages/airflow/utils/email.py", line 318, in _get_smtp_connection
    return smtplib.SMTP(host=host, port=port, timeout=timeout)
           ^^^^^^^^^^^^^^^^^^^^^^^^^^^^^^^^^^^^^^^^^^^^^^^^^^^
  File "/usr/lib/python3.12/smtplib.py", line 255, in __init__
    (code, msg) = self.connect(host, port)
                  ^^^^^^^^^^^^^^^^^^^^^^^^
  File "/usr/lib/python3.12/smtplib.py", line 341, in connect
    self.sock = self._get_socket(host, port, self.timeout)
                ^^^^^^^^^^^^^^^^^^^^^^^^^^^^^^^^^^^^^^^^^^
  File "/usr/lib/python3.12/smtplib.py", line 312, in _get_socket
    return socket.create_connection((host, port), timeout,
           ^^^^^^^^^^^^^^^^^^^^^^^^^^^^^^^^^^^^^^^^^^^^^^^
  File "/usr/lib/python3.12/socket.py", line 852, in create_connection
    raise exceptions[0]
  File "/usr/lib/python3.12/socket.py", line 837, in create_connection
    sock.connect(sa)
ConnectionRefusedError: [Errno 111] Connection refused
[2025-03-22T21:57:42.464+0000] {taskinstance.py:341} INFO - ::group::Post task execution logs
[2025-03-22T21:57:42.464+0000] {standard_task_runner.py:124} ERROR - Failed to execute job 108 for task create_tables (name 'hchgscgs' is not defined; 529106)
Traceback (most recent call last):
  File "/home/usmail/sys_fraud/sys_detection_frauds/lib/python3.12/site-packages/airflow/task/task_runner/standard_task_runner.py", line 117, in _start_by_fork
    ret = args.func(args, dag=self.dag)
          ^^^^^^^^^^^^^^^^^^^^^^^^^^^^^
  File "/home/usmail/sys_fraud/sys_detection_frauds/lib/python3.12/site-packages/airflow/cli/cli_config.py", line 49, in command
    return func(*args, **kwargs)
           ^^^^^^^^^^^^^^^^^^^^^
  File "/home/usmail/sys_fraud/sys_detection_frauds/lib/python3.12/site-packages/airflow/utils/cli.py", line 116, in wrapper
    return f(*args, **kwargs)
           ^^^^^^^^^^^^^^^^^^
  File "/home/usmail/sys_fraud/sys_detection_frauds/lib/python3.12/site-packages/airflow/cli/commands/task_command.py", line 483, in task_run
    task_return_code = _run_task_by_selected_method(args, _dag, ti)
                       ^^^^^^^^^^^^^^^^^^^^^^^^^^^^^^^^^^^^^^^^^^^^
  File "/home/usmail/sys_fraud/sys_detection_frauds/lib/python3.12/site-packages/airflow/cli/commands/task_command.py", line 256, in _run_task_by_selected_method
    return _run_raw_task(args, ti)
           ^^^^^^^^^^^^^^^^^^^^^^^
  File "/home/usmail/sys_fraud/sys_detection_frauds/lib/python3.12/site-packages/airflow/cli/commands/task_command.py", line 341, in _run_raw_task
    return ti._run_raw_task(
           ^^^^^^^^^^^^^^^^^
  File "/home/usmail/sys_fraud/sys_detection_frauds/lib/python3.12/site-packages/airflow/utils/session.py", line 97, in wrapper
    return func(*args, session=session, **kwargs)
           ^^^^^^^^^^^^^^^^^^^^^^^^^^^^^^^^^^^^^^
  File "/home/usmail/sys_fraud/sys_detection_frauds/lib/python3.12/site-packages/airflow/models/taskinstance.py", line 3006, in _run_raw_task
    return _run_raw_task(
           ^^^^^^^^^^^^^^
  File "/home/usmail/sys_fraud/sys_detection_frauds/lib/python3.12/site-packages/airflow/models/taskinstance.py", line 274, in _run_raw_task
    TaskInstance._execute_task_with_callbacks(
  File "/home/usmail/sys_fraud/sys_detection_frauds/lib/python3.12/site-packages/airflow/models/taskinstance.py", line 3161, in _execute_task_with_callbacks
    result = self._execute_task(context, task_orig)
             ^^^^^^^^^^^^^^^^^^^^^^^^^^^^^^^^^^^^^^
  File "/home/usmail/sys_fraud/sys_detection_frauds/lib/python3.12/site-packages/airflow/models/taskinstance.py", line 3185, in _execute_task
    return _execute_task(self, context, task_orig)
           ^^^^^^^^^^^^^^^^^^^^^^^^^^^^^^^^^^^^^^^
  File "/home/usmail/sys_fraud/sys_detection_frauds/lib/python3.12/site-packages/airflow/models/taskinstance.py", line 763, in _execute_task
    result = _execute_callable(context=context, **execute_callable_kwargs)
             ^^^^^^^^^^^^^^^^^^^^^^^^^^^^^^^^^^^^^^^^^^^^^^^^^^^^^^^^^^^^^
  File "/home/usmail/sys_fraud/sys_detection_frauds/lib/python3.12/site-packages/airflow/models/taskinstance.py", line 734, in _execute_callable
    return ExecutionCallableRunner(
           ^^^^^^^^^^^^^^^^^^^^^^^^
  File "/home/usmail/sys_fraud/sys_detection_frauds/lib/python3.12/site-packages/airflow/utils/operator_helpers.py", line 252, in run
    return self.func(*args, **kwargs)
           ^^^^^^^^^^^^^^^^^^^^^^^^^^
  File "/home/usmail/sys_fraud/sys_detection_frauds/lib/python3.12/site-packages/airflow/models/baseoperator.py", line 424, in wrapper
    return func(self, *args, **kwargs)
           ^^^^^^^^^^^^^^^^^^^^^^^^^^^
  File "/home/usmail/sys_fraud/sys_detection_frauds/lib/python3.12/site-packages/airflow/operators/python.py", line 238, in execute
    return_value = self.execute_callable()
                   ^^^^^^^^^^^^^^^^^^^^^^^
  File "/home/usmail/sys_fraud/sys_detection_frauds/lib/python3.12/site-packages/airflow/operators/python.py", line 256, in execute_callable
    return runner.run(*self.op_args, **self.op_kwargs)
           ^^^^^^^^^^^^^^^^^^^^^^^^^^^^^^^^^^^^^^^^^^^
  File "/home/usmail/sys_fraud/sys_detection_frauds/lib/python3.12/site-packages/airflow/utils/operator_helpers.py", line 252, in run
    return self.func(*args, **kwargs)
           ^^^^^^^^^^^^^^^^^^^^^^^^^^
  File "/home/usmail/sys_fraud/sys_detection_frauds/system_fraud_transactions_detection/airflow_home/dags/dags.py", line 206, in create_tables
    hchgscgs
NameError: name 'hchgscgs' is not defined
[2025-03-22T21:57:42.481+0000] {local_task_job_runner.py:266} INFO - Task exited with return code 1
[2025-03-22T21:57:42.501+0000] {taskinstance.py:3901} INFO - 0 downstream tasks scheduled from follow-on schedule check
[2025-03-22T21:57:42.502+0000] {local_task_job_runner.py:245} INFO - ::endgroup::
