[2025-03-21T22:42:31.362+0000] {local_task_job_runner.py:123} INFO - ::group::Pre task execution logs
[2025-03-21T22:42:31.372+0000] {taskinstance.py:2614} INFO - Dependencies all met for dep_context=non-requeueable deps ti=<TaskInstance: fraud_detection_pipeline.fetch_data scheduled__2025-03-20T00:00:00+00:00 [queued]>
[2025-03-21T22:42:31.376+0000] {taskinstance.py:2614} INFO - Dependencies all met for dep_context=requeueable deps ti=<TaskInstance: fraud_detection_pipeline.fetch_data scheduled__2025-03-20T00:00:00+00:00 [queued]>
[2025-03-21T22:42:31.377+0000] {taskinstance.py:2867} INFO - Starting attempt 2 of 4
[2025-03-21T22:42:31.389+0000] {taskinstance.py:2890} INFO - Executing <Task(PythonOperator): fetch_data> on 2025-03-20 00:00:00+00:00
[2025-03-21T22:42:31.392+0000] {standard_task_runner.py:72} INFO - Started process 3774851 to run task
[2025-03-21T22:42:31.394+0000] {standard_task_runner.py:104} INFO - Running: ['airflow', 'tasks', 'run', 'fraud_detection_pipeline', 'fetch_data', 'scheduled__2025-03-20T00:00:00+00:00', '--job-id', '5', '--raw', '--subdir', 'DAGS_FOLDER/dags.py', '--cfg-path', '/tmp/tmp9iyjyqow']
[2025-03-21T22:42:31.396+0000] {standard_task_runner.py:105} INFO - Job 5: Subtask fetch_data
[2025-03-21T22:42:31.437+0000] {task_command.py:467} INFO - Running <TaskInstance: fraud_detection_pipeline.fetch_data scheduled__2025-03-20T00:00:00+00:00 [running]> on host usmail-ThinkBook-14-G2-ITL
[2025-03-21T22:42:31.511+0000] {taskinstance.py:3134} INFO - Exporting env vars: AIRFLOW_CTX_DAG_OWNER='airflow' AIRFLOW_CTX_DAG_ID='fraud_detection_pipeline' AIRFLOW_CTX_TASK_ID='fetch_data' AIRFLOW_CTX_EXECUTION_DATE='2025-03-20T00:00:00+00:00' AIRFLOW_CTX_TRY_NUMBER='2' AIRFLOW_CTX_DAG_RUN_ID='scheduled__2025-03-20T00:00:00+00:00'
[2025-03-21T22:42:31.512+0000] {taskinstance.py:732} INFO - ::endgroup::
[2025-03-21T22:42:31.533+0000] {logging_mixin.py:190} WARNING - 2025-03-21 22:42:31,533 - unusual_prefix_4468d1768859daca68fcd8a1524a05768ee368d9_dags - ERROR - Error fetching data from API: 500 Server Error: Internal Server Error for url: http://localhost:8000/api/v1/customer
[2025-03-21T22:42:31.533+0000] {dags.py:58} ERROR - Error fetching data from API: 500 Server Error: Internal Server Error for url: http://localhost:8000/api/v1/customer
[2025-03-21T22:42:31.533+0000] {taskinstance.py:3313} ERROR - Task failed with exception
Traceback (most recent call last):
  File "/home/usmail/sys_fraud/sys_detection_frauds/lib/python3.12/site-packages/airflow/models/taskinstance.py", line 763, in _execute_task
    result = _execute_callable(context=context, **execute_callable_kwargs)
             ^^^^^^^^^^^^^^^^^^^^^^^^^^^^^^^^^^^^^^^^^^^^^^^^^^^^^^^^^^^^^
  File "/home/usmail/sys_fraud/sys_detection_frauds/lib/python3.12/site-packages/airflow/models/taskinstance.py", line 734, in _execute_callable
    return ExecutionCallableRunner(
           ^^^^^^^^^^^^^^^^^^^^^^^^
  File "/home/usmail/sys_fraud/sys_detection_frauds/lib/python3.12/site-packages/airflow/utils/operator_helpers.py", line 252, in run
    return self.func(*args, **kwargs)
           ^^^^^^^^^^^^^^^^^^^^^^^^^^
  File "/home/usmail/sys_fraud/sys_detection_frauds/lib/python3.12/site-packages/airflow/models/baseoperator.py", line 424, in wrapper
    return func(self, *args, **kwargs)
           ^^^^^^^^^^^^^^^^^^^^^^^^^^^
  File "/home/usmail/sys_fraud/sys_detection_frauds/lib/python3.12/site-packages/airflow/operators/python.py", line 238, in execute
    return_value = self.execute_callable()
                   ^^^^^^^^^^^^^^^^^^^^^^^
  File "/home/usmail/sys_fraud/sys_detection_frauds/lib/python3.12/site-packages/airflow/operators/python.py", line 256, in execute_callable
    return runner.run(*self.op_args, **self.op_kwargs)
           ^^^^^^^^^^^^^^^^^^^^^^^^^^^^^^^^^^^^^^^^^^^
  File "/home/usmail/sys_fraud/sys_detection_frauds/lib/python3.12/site-packages/airflow/utils/operator_helpers.py", line 252, in run
    return self.func(*args, **kwargs)
           ^^^^^^^^^^^^^^^^^^^^^^^^^^
  File "/home/usmail/sys_fraud/sys_detection_frauds/system_fraud_transactions_detection/airflow_home/dags/dags.py", line 50, in fetch_data
    response.raise_for_status()
  File "/home/usmail/sys_fraud/sys_detection_frauds/lib/python3.12/site-packages/requests/models.py", line 1024, in raise_for_status
    raise HTTPError(http_error_msg, response=self)
requests.exceptions.HTTPError: 500 Server Error: Internal Server Error for url: http://localhost:8000/api/v1/customer
[2025-03-21T22:42:31.540+0000] {taskinstance.py:1226} INFO - Marking task as UP_FOR_RETRY. dag_id=fraud_detection_pipeline, task_id=fetch_data, run_id=scheduled__2025-03-20T00:00:00+00:00, execution_date=20250320T000000, start_date=20250321T224231, end_date=20250321T224231
[2025-03-21T22:42:31.557+0000] {taskinstance.py:341} INFO - ::group::Post task execution logs
[2025-03-21T22:42:31.557+0000] {standard_task_runner.py:124} ERROR - Failed to execute job 5 for task fetch_data (500 Server Error: Internal Server Error for url: http://localhost:8000/api/v1/customer; 3774851)
Traceback (most recent call last):
  File "/home/usmail/sys_fraud/sys_detection_frauds/lib/python3.12/site-packages/airflow/task/task_runner/standard_task_runner.py", line 117, in _start_by_fork
    ret = args.func(args, dag=self.dag)
          ^^^^^^^^^^^^^^^^^^^^^^^^^^^^^
  File "/home/usmail/sys_fraud/sys_detection_frauds/lib/python3.12/site-packages/airflow/cli/cli_config.py", line 49, in command
    return func(*args, **kwargs)
           ^^^^^^^^^^^^^^^^^^^^^
  File "/home/usmail/sys_fraud/sys_detection_frauds/lib/python3.12/site-packages/airflow/utils/cli.py", line 116, in wrapper
    return f(*args, **kwargs)
           ^^^^^^^^^^^^^^^^^^
  File "/home/usmail/sys_fraud/sys_detection_frauds/lib/python3.12/site-packages/airflow/cli/commands/task_command.py", line 483, in task_run
    task_return_code = _run_task_by_selected_method(args, _dag, ti)
                       ^^^^^^^^^^^^^^^^^^^^^^^^^^^^^^^^^^^^^^^^^^^^
  File "/home/usmail/sys_fraud/sys_detection_frauds/lib/python3.12/site-packages/airflow/cli/commands/task_command.py", line 256, in _run_task_by_selected_method
    return _run_raw_task(args, ti)
           ^^^^^^^^^^^^^^^^^^^^^^^
  File "/home/usmail/sys_fraud/sys_detection_frauds/lib/python3.12/site-packages/airflow/cli/commands/task_command.py", line 341, in _run_raw_task
    return ti._run_raw_task(
           ^^^^^^^^^^^^^^^^^
  File "/home/usmail/sys_fraud/sys_detection_frauds/lib/python3.12/site-packages/airflow/utils/session.py", line 97, in wrapper
    return func(*args, session=session, **kwargs)
           ^^^^^^^^^^^^^^^^^^^^^^^^^^^^^^^^^^^^^^
  File "/home/usmail/sys_fraud/sys_detection_frauds/lib/python3.12/site-packages/airflow/models/taskinstance.py", line 3006, in _run_raw_task
    return _run_raw_task(
           ^^^^^^^^^^^^^^
  File "/home/usmail/sys_fraud/sys_detection_frauds/lib/python3.12/site-packages/airflow/models/taskinstance.py", line 274, in _run_raw_task
    TaskInstance._execute_task_with_callbacks(
  File "/home/usmail/sys_fraud/sys_detection_frauds/lib/python3.12/site-packages/airflow/models/taskinstance.py", line 3161, in _execute_task_with_callbacks
    result = self._execute_task(context, task_orig)
             ^^^^^^^^^^^^^^^^^^^^^^^^^^^^^^^^^^^^^^
  File "/home/usmail/sys_fraud/sys_detection_frauds/lib/python3.12/site-packages/airflow/models/taskinstance.py", line 3185, in _execute_task
    return _execute_task(self, context, task_orig)
           ^^^^^^^^^^^^^^^^^^^^^^^^^^^^^^^^^^^^^^^
  File "/home/usmail/sys_fraud/sys_detection_frauds/lib/python3.12/site-packages/airflow/models/taskinstance.py", line 763, in _execute_task
    result = _execute_callable(context=context, **execute_callable_kwargs)
             ^^^^^^^^^^^^^^^^^^^^^^^^^^^^^^^^^^^^^^^^^^^^^^^^^^^^^^^^^^^^^
  File "/home/usmail/sys_fraud/sys_detection_frauds/lib/python3.12/site-packages/airflow/models/taskinstance.py", line 734, in _execute_callable
    return ExecutionCallableRunner(
           ^^^^^^^^^^^^^^^^^^^^^^^^
  File "/home/usmail/sys_fraud/sys_detection_frauds/lib/python3.12/site-packages/airflow/utils/operator_helpers.py", line 252, in run
    return self.func(*args, **kwargs)
           ^^^^^^^^^^^^^^^^^^^^^^^^^^
  File "/home/usmail/sys_fraud/sys_detection_frauds/lib/python3.12/site-packages/airflow/models/baseoperator.py", line 424, in wrapper
    return func(self, *args, **kwargs)
           ^^^^^^^^^^^^^^^^^^^^^^^^^^^
  File "/home/usmail/sys_fraud/sys_detection_frauds/lib/python3.12/site-packages/airflow/operators/python.py", line 238, in execute
    return_value = self.execute_callable()
                   ^^^^^^^^^^^^^^^^^^^^^^^
  File "/home/usmail/sys_fraud/sys_detection_frauds/lib/python3.12/site-packages/airflow/operators/python.py", line 256, in execute_callable
    return runner.run(*self.op_args, **self.op_kwargs)
           ^^^^^^^^^^^^^^^^^^^^^^^^^^^^^^^^^^^^^^^^^^^
  File "/home/usmail/sys_fraud/sys_detection_frauds/lib/python3.12/site-packages/airflow/utils/operator_helpers.py", line 252, in run
    return self.func(*args, **kwargs)
           ^^^^^^^^^^^^^^^^^^^^^^^^^^
  File "/home/usmail/sys_fraud/sys_detection_frauds/system_fraud_transactions_detection/airflow_home/dags/dags.py", line 50, in fetch_data
    response.raise_for_status()
  File "/home/usmail/sys_fraud/sys_detection_frauds/lib/python3.12/site-packages/requests/models.py", line 1024, in raise_for_status
    raise HTTPError(http_error_msg, response=self)
requests.exceptions.HTTPError: 500 Server Error: Internal Server Error for url: http://localhost:8000/api/v1/customer
[2025-03-21T22:42:31.607+0000] {local_task_job_runner.py:266} INFO - Task exited with return code 1
[2025-03-21T22:42:31.640+0000] {taskinstance.py:3901} INFO - 0 downstream tasks scheduled from follow-on schedule check
[2025-03-21T22:42:31.641+0000] {local_task_job_runner.py:245} INFO - ::endgroup::
